<?xml version="1.0" encoding="UTF-8"?>
<robot name="Robot">
    <link name="abstract_chassis_link">
        <inertial>
          <origin xyz="0.00703065 -0.00001010 0.21569964" rpy="0 0 0" />
          <mass value="50.96231322" />
          <inertia ixx="3.27070589" ixy="0.00010827" ixz="-0.18468600" iyy="3.37047588" iyz="0.00035735" izz="2.72731093" />
        </inertial>
        <visual>
            <origin xyz="0 0 0" rpy="0 0 0" />
            <geometry>
                <mesh filename="package://meshes/stl_output/base_link_reduced.STL" />
            </geometry>
            <material name="al">
                <color rgba="0 0.6 1 1" />
            </material>
        </visual>
        <collision>
            <origin xyz="0 0 0" rpy="0 0 0" />
            <geometry>
                <mesh filename="package://meshes/stl_output/base_link_reduced.STL" />
            </geometry>
        </collision>
    </link>
    <link name="base">
        <inertial>
            <mass value="0"/>
            <inertia ixx="0" ixy="0" ixz="0" iyy="0" iyz="0" izz="0"/>
        </inertial>
    </link>
    <link name="base_link_x">
        <inertial>
            <origin rpy="0.00000000 0.00000000 0.00000000" xyz="0.00000000 0.00000000 0.00000000"/>
            <mass value="1.00000000"/>
            <inertia ixx="1.00000000" ixy="0.00000000" ixz="0.00000000" iyy="1.00000000" iyz="0.00000000" izz="1.00000000"/>
        </inertial>
    </link>
    <link name="base_link_y">
        <inertial>
            <origin rpy="0.00000000 0.00000000 0.00000000" xyz="0.00000000 0.00000000 0.00000000"/>
            <mass value="1.00000000"/>
            <inertia ixx="1.00000000" ixy="0.00000000" ixz="0.00000000" iyy="1.00000000" iyz="0.00000000" izz="1.00000000"/>
        </inertial>
    </link>
    <link name="left_arm_base_link">
        <inertial>
          <origin xyz="-0.0005634 0.038934 3.1874E-06" rpy="0 0 0" />
          <mass value="1.658" />
          <inertia ixx="0.0010597" ixy="1.9821E-05" ixz="-1.6752E-07" iyy="0.0011787" iyz="-1.9146E-07" izz="0.0010647" />
        </inertial>
        <visual>
            <origin xyz="0 0 0" rpy="0 0 0" />
            <geometry>
                <mesh filename="package://meshes/stl_output/left_arm_base_link_reduced.STL" />
            </geometry>
            <material name="">
                <color rgba="0.79216 0.81961 0.93333 1" />
            </material>
        </visual>
        <collision>
            <origin xyz="0 0 0" rpy="0 0 0" />
            <geometry>
                <mesh filename="package://meshes/stl_output/left_arm_base_link_reduced.STL" />
            </geometry>
        </collision>
    </link>
    <link name="left_arm_link1">
        <inertial>
          <origin xyz="0.000015 0.105259 -0.001954" rpy="0 0 0" />
          <mass value="1.164" />
          <inertia ixx="0.001125" ixy="0.0" ixz="0.0" iyy="0.001084" iyz="-0.000023" izz="0.001158" />
        </inertial>
      <visual>
            <origin xyz="0 0 0" rpy="0 0 0" />
            <geometry>
                <mesh filename="package://meshes/stl_output/left_arm_link1_reduced.STL" />
            </geometry>
            <material name="">
                <color rgba="0.79216 0.81961 0.93333 1" />
            </material>
        </visual>
        <collision>
            <origin xyz="0 0 0" rpy="0 0 0" />
            <geometry>
                <mesh filename="package://meshes/stl_output/left_arm_link1_reduced.STL" />
            </geometry>
        </collision>
    </link>
    <link name="left_arm_link2">
        <inertial>
          <origin xyz="-0.23622 0.016352 -0.00013275" rpy="0 0 0" />
          <mass value="1.3" />
          <inertia ixx="0.00060638" ixy="0.00041817" ixz="0.00014956" iyy="0.0075936" iyz="-8.0916E-06" izz="0.0075712" />
        </inertial>
        <visual>
            <origin xyz="0 0 0" rpy="0 0 0" />
            <geometry>
                <mesh filename="package://meshes/stl_output/left_arm_link2_reduced.STL" />
            </geometry>
            <material name="">
                <color rgba="0.79216 0.81961 0.93333 1" />
            </material>
        </visual>
        <collision>
            <origin xyz="0 0 0" rpy="0 0 0" />
            <geometry>
                <mesh filename="package://meshes/stl_output/left_arm_link2_reduced.STL" />
            </geometry>
        </collision>
    </link>
    <link name="left_arm_link3">
        <inertial>
          <origin xyz="0.045114 0.054616 -0.00045593" rpy="0 0 0" />
          <mass value="0.818" />
          <inertia ixx="0.00060107" ixy="-0.00022467" ixz="-7.1194E-06" iyy="0.0013959" iyz="-9.7503E-06" izz="0.0015027" />
        </inertial>
        <visual>
            <origin xyz="0 0 0" rpy="0 0 0" />
            <geometry>
                <mesh filename="package://meshes/stl_output/left_arm_link3_reduced.STL" />
            </geometry>
            <material name="">
                <color rgba="0.79216 0.81961 0.93333 1" />
            </material>
        </visual>
        <collision>
            <origin xyz="0 0 0" rpy="0 0 0" />
            <geometry>
                <mesh filename="package://meshes/stl_output/left_arm_link3_reduced.STL" />
            </geometry>
        </collision>
    </link>
    <link name="left_arm_link4">
        <inertial>
          <origin xyz="0.24285 0.0023784 1.279E-06" rpy="0 0 0" />
          <mass value="0.698" />
          <inertia ixx="8.45E-05" ixy="-8.2627E-07" ixz="-2.2607E-09" iyy="0.00010174" iyz="5.3612E-09" izz="9.7044E-05" />
        </inertial>
        <visual>
            <origin xyz="0 0 0" rpy="0 0 0" />
            <geometry>
                <mesh filename="package://meshes/stl_output/left_arm_link4_reduced.STL" />
            </geometry>
            <material name="">
                <color rgba="1 1 1 1" />
            </material>
        </visual>
        <collision>
            <origin xyz="0 0 0" rpy="0 0 0" />
            <geometry>
                <mesh filename="package://meshes/stl_output/left_arm_link4_reduced.STL" />
            </geometry>
        </collision>
    </link>
    <link name="left_arm_link5">
        <inertial>
          <origin xyz="0.054309 0.0041811 4.0699E-06" rpy="0 0 0" />
          <mass value="0.417" />
          <inertia ixx="8.3999E-05" ixy="1.6234E-05" ixz="7.4127E-08" iyy="9.8498E-05" iyz="-1.3811E-08" izz="0.00011333" />
        </inertial>
        <visual>
            <origin xyz="0 0 0" rpy="0 0 0" />
            <geometry>
                <mesh filename="package://meshes/stl_output/left_arm_link5_reduced.STL" />
            </geometry>
            <material name="">
                <color rgba="1 1 1 1" />
            </material>
        </visual>
        <collision>
            <origin xyz="0 0 0" rpy="0 0 0" />
            <geometry>
                <mesh filename="package://meshes/stl_output/left_arm_link5_reduced.STL" />
            </geometry>
        </collision>
    </link>
    <link name="left_arm_link6">
        <inertial>
          <origin xyz="0.028138 1.2134E-07 5.4049E-08" rpy="0 0 0" />
          <mass value="0.037" />
          <inertia ixx="3.5662E-06" ixy="6.6514E-12" ixz="2.9628E-12" iyy="2.0238E-06" iyz="-4.1666E-12" izz="2.0238E-06" />
        </inertial>
        <visual>
            <origin xyz="0 0 0" rpy="0 0 0" />
            <geometry>
                <mesh filename="package://meshes/stl_output/left_arm_link6_reduced.STL" />
            </geometry>
            <material name="">
                <color rgba="0.82353 0.82353 1 1" />
            </material>
        </visual>
        <collision>
            <origin xyz="0 0 0" rpy="0 0 0" />
            <geometry>
                <mesh filename="package://meshes/stl_output/left_arm_link6_reduced.STL" />
            </geometry>
        </collision>
    </link>
    <link name="left_gripper_link">
        <inertial>
          <origin xyz="-0.031107 -1.3893E-07 -1.437E-07" rpy="0 0 0" />
          <mass value="0.604" />
          <inertia ixx="0.00017588" ixy="4.1789E-10" ixz="-5.3493E-10" iyy="9.8637E-05" iyz="-8.1856E-08" izz="0.00016512" />
        </inertial>
        <visual>
            <origin xyz="0 0 0" rpy="0 0 0" />
            <geometry>
                <mesh filename="package://meshes/stl_output/end_effector_reduced.STL" />
            </geometry>
            <material name="">
                <color rgba="0.82353 0.82353 1 1" />
            </material>
        </visual>
        <collision>
            <origin xyz="0 0 0" rpy="0 0 0" />
            <geometry>
                <mesh filename="package://meshes/stl_output/end_effector_reduced.STL" />
            </geometry>
        </collision>
    </link>
    <joint name="arm_mount_joint" type="fixed">
        <parent link="abstract_chassis_link"/>
        <child link="left_arm_base_link"/>
        <origin rpy="0.00000000  0.00000000 -1.57080000" xyz="0.15995000 0.00000000 0.94650000"/>
        <axis xyz="100"/>
    </joint>
    <joint name="joint_theta" type="revolute">
        <parent link="base_link_y"/>
        <child link="abstract_chassis_link"/>
        <origin rpy="0.00000000 0.00000000 0.00000000" xyz="0.00000000 0.00000000 0.00000000"/>
        <axis xyz="0.00000000 0.00000000 1.00000000"/>
        <limit lower="-Inf" upper="Inf" effort="0" velocity="0"/>
    </joint>
    <joint name="joint_x" type="prismatic">
        <parent link="base"/>
        <child link="base_link_x"/>
        <origin rpy="0.00000000 0.00000000 0.00000000" xyz="0.00000000 0.00000000 0.00000000"/>
        <axis xyz="0.00000000 0.00000000 1.00000000"/>
        <limit lower="-50.00000000" upper="50.00000000" effort="0" velocity="0"/>
    </joint>
    <joint name="joint_y" type="prismatic">
        <parent link="base_link_x"/>
        <child link="base_link_y"/>
        <origin rpy="0.00000000 0.00000000 0.00000000" xyz="0.00000000 0.00000000 0.00000000"/>
        <axis xyz="0.00000000 1.00000000 0.00000000"/>
        <limit lower="-50.00000000" upper="50.00000000" effort="0" velocity="0"/>
    </joint>
  <joint name="left_arm_joint1" type="revolute">
    <origin xyz="-0.0011149 0.0446 0" rpy="0 0 0" />
    <parent link="left_arm_base_link" />
    <child link="left_arm_link1" />
    <axis xyz="0 1 0" />
    <limit lower="-2.8798" upper="2.8798" effort="40" velocity="1.6" />
  </joint>
  <joint name="left_arm_joint2" type="revolute">
    <origin xyz="0 0.1061 0" rpy="0 0 0" />
    <parent link="left_arm_link1" />
    <child link="left_arm_link2" />
    <axis xyz="0 0 -1" />
    <limit lower="0" upper="3.2289" effort="40" velocity="1.6" />
  </joint>
  <joint name="left_arm_joint3" type="revolute">
    <origin xyz="-0.34928 0.019998 0" rpy="0 0 0" />
    <parent link="left_arm_link2" />
    <child link="left_arm_link3" />
    <axis xyz="0 0 -1" />
    <limit lower="-3.3161" upper="0" effort="27" velocity="4.0" />
  </joint>
  <joint name="left_arm_joint4" type="revolute">
    <origin xyz="0.02735 0.069767 0" rpy="0 0 0" />
    <parent link="left_arm_link3" />
    <child link="left_arm_link4" />
    <axis xyz="1 0 0" />
    <limit lower="-2.8798" upper="2.8798" effort="7" velocity="4.0" />
  </joint>
  <joint name="left_arm_joint5" type="revolute">
    <origin xyz="0.2463 -0.00049894 0" rpy="0 0 0" />
    <parent link="left_arm_link4" />
    <child link="left_arm_link5" />
    <axis xyz="0 1 0" />
    <limit lower="-1.6581" upper="1.6581" effort="7" velocity="4.0" />
  </joint>
  <joint name="left_arm_joint6" type="revolute">
    <origin xyz="0.058249 0.00050025 0" rpy="0 0 0" />
    <parent link="left_arm_link5" />
    <child link="left_arm_link6" />
    <axis xyz="1 0 0" />
    <limit lower="-2.8798" upper="2.8798" effort="7" velocity="4.0" />
  </joint>
  <joint name="left_gripper_joint" type="fixed">
    <origin xyz="0.1039 0 0" rpy="0 0 0" />
    <parent link="left_arm_link6" />
    <child link="left_gripper_link" />
    <axis xyz="0 0 0" />
  </joint>

</robot>
