<?xml version="1.0" encoding="utf-8"?>
<robot name="recomoProto1_posonly">
  <link name="base_root" />
  <link name="base_vx_link" />
  <link name="base_vy_link" />
  <link name="base_wz_link" />

  <joint name="base_joint_vx" type="prismatic">
    <origin xyz="0 0 0" rpy="0 0 0" />
    <parent link="base_root" />
    <child link="base_vx_link" />
    <axis xyz="1 0 0" />
    <limit lower="-50" upper="50" effort="200" velocity="2" />
  </joint>

  <joint name="base_joint_vy" type="prismatic">
    <origin xyz="0 0 0" rpy="0 0 0" />
    <parent link="base_vx_link" />
    <child link="base_vy_link" />
    <axis xyz="0 1 0" />
    <limit lower="-50" upper="50" effort="200" velocity="2" />
  </joint>

  <joint name="base_joint_wz" type="continuous">
    <origin xyz="0 0 0" rpy="0 0 0" />
    <parent link="base_vy_link" />
    <child link="base_wz_link" />
    <axis xyz="0 0 1" />
  </joint>

  <link name="base_link">
    <inertial>
      <origin xyz="0.00046908 -2.8187E-06 0.2503" rpy="0 0 0" />
      <mass value="5.7875" />
      <inertia ixx="0.032786" ixy="0.00070047" ixz="2.6967E-07" iyy="0.031496" iyz="2.9091E-07" izz="0.04864" />
    </inertial>
    <visual>
      <origin xyz="0 0 0" rpy="0 0 0" />
      <geometry>
        <mesh filename="package://recomoProto1/meshes/base_link.STL" />
      </geometry>
      <material name="">
        <color rgba="1 0.6 0 1" />
      </material>
    </visual>
    <collision>
      <origin xyz="0 0 0" rpy="0 0 0" />
      <geometry>
        <mesh filename="package://recomoProto1/meshes/base_link.STL" />
      </geometry>
    </collision>
  </link>

  <joint name="base_link_fixed" type="fixed">
    <origin xyz="0 0 0" rpy="0 0 0" />
    <parent link="base_wz_link" />
    <child link="base_link" />
  </joint>

  <link name="arm_base_Link">
    <inertial>
      <origin xyz="5.1719E-10 -7.2053E-10 0.047751" rpy="0 0 0" />
      <mass value="0.24438" />
      <inertia ixx="0.00026807" ixy="-2.4035E-12" ixz="-4.3281E-13" iyy="0.00021563" iyz="-3.9641E-14" izz="0.00022178" />
    </inertial>
    <visual>
      <origin xyz="0 0 0" rpy="0 0 0" />
      <geometry>
        <mesh filename="package://recomoProto1/meshes/arm_base_Link.STL" />
      </geometry>
      <material name="">
        <color rgba="0.65098 0.63922 0.76863 1" />
      </material>
    </visual>
    <collision>
      <origin xyz="0 0 0" rpy="0 0 0" />
      <geometry>
        <mesh filename="package://recomoProto1/meshes/arm_base_Link.STL" />
      </geometry>
    </collision>
  </link>

  <joint name="arm_base_joint" type="fixed">
    <origin xyz="0.00047949 0 0.7424" rpy="0 0 0" />
    <parent link="base_link" />
    <child link="arm_base_Link" />
  </joint>

  <link name="arm_link_1">
    <inertial>
      <origin xyz="-8.7388E-05 0.019068 0.037442" rpy="0 0 0" />
      <mass value="0.25507" />
      <inertia ixx="0.00012087" ixy="7.1673E-07" ixz="2.9536E-07" iyy="0.00013242" iyz="-7.0821E-06" izz="0.00015199" />
    </inertial>
    <visual>
      <origin xyz="0 0 0" rpy="0 0 0" />
      <geometry>
        <mesh filename="package://recomoProto1/meshes/arm_link_1.STL" />
      </geometry>
      <material name="">
        <color rgba="0.81176 0.84314 0.9098 1" />
      </material>
    </visual>
    <collision>
      <origin xyz="0 0 0" rpy="0 0 0" />
      <geometry>
        <mesh filename="package://recomoProto1/meshes/arm_link_1.STL" />
      </geometry>
    </collision>
  </link>

  <joint name="joint6_arm_yaw" type="revolute">
    <origin xyz="0 0 0.1004" rpy="0 0 0" />
    <parent link="arm_base_Link" />
    <child link="arm_link_1" />
    <axis xyz="0 0 1" />
    <limit lower="-3.1416" upper="3.1416" effort="30" velocity="0.5" />
  </joint>

  <link name="arm_link_2">
    <inertial>
      <origin xyz="-6.5027E-08 0.098704 0.038532" rpy="0 0 0" />
      <mass value="0.30483" />
      <inertia ixx="0.00058347" ixy="-1.9725E-10" ixz="-1.9794E-11" iyy="0.00015774" iyz="-1.9451E-07" izz="0.00067361" />
    </inertial>
    <visual>
      <origin xyz="0 0 0" rpy="0 0 0" />
      <geometry>
        <mesh filename="package://recomoProto1/meshes/arm_link_2.STL" />
      </geometry>
      <material name="">
        <color rgba="0.61176 0.65882 0.67059 1" />
      </material>
    </visual>
    <collision>
      <origin xyz="0 0 0" rpy="0 0 0" />
      <geometry>
        <mesh filename="package://recomoProto1/meshes/arm_link_2.STL" />
      </geometry>
    </collision>
  </link>

  <joint name="joint5_arm_pitch" type="revolute">
    <origin xyz="0 0 0.044" rpy="1.5708 0 0" />
    <parent link="arm_link_1" />
    <child link="arm_link_2" />
    <axis xyz="0 0 1" />
    <limit lower="-1.5708" upper="1.5708" effort="30" velocity="0.5" />
  </joint>

  <link name="arm_link_3">
    <inertial>
      <origin xyz="-0.0060716 -0.14927 0.010538" rpy="0 0 0" />
      <mass value="0.62022" />
      <inertia ixx="0.00045002" ixy="7.6788E-07" ixz="6.7551E-07" iyy="0.0003947" iyz="8.8791E-06" izz="0.00051466" />
    </inertial>
    <visual>
      <origin xyz="0 0 0" rpy="0 0 0" />
      <geometry>
        <mesh filename="package://recomoProto1/meshes/arm_link_3.STL" />
      </geometry>
      <material name="">
        <color rgba="0.79216 0.81961 0.93333 1" />
      </material>
    </visual>
    <collision>
      <origin xyz="0 0 0" rpy="0 0 0" />
      <geometry>
        <mesh filename="package://recomoProto1/meshes/arm_link_3.STL" />
      </geometry>
    </collision>
  </link>

  <joint name="joint4_elbow_pitch" type="revolute">
    <origin xyz="0 0.2 0" rpy="3.1416 0 0" />
    <parent link="arm_link_2" />
    <child link="arm_link_3" />
    <axis xyz="0 0 1" />
    <limit lower="-1.57" upper="1.57" effort="30" velocity="0.5" />
  </joint>

  <link name="ee_tool">
    <inertial>
      <origin xyz="0 0 0" rpy="0 0 0" />
      <mass value="0.001" />
      <inertia ixx="2.3333E-07" ixy="0" ixz="0" iyy="2.3333E-07" iyz="0" izz="5.0E-08" />
    </inertial>
  </link>

  <joint name="ee_tool_fixed" type="fixed">
    <origin xyz="0 -0.31584 0" rpy="1.5708 0 0" />
    <parent link="arm_link_3" />
    <child link="ee_tool" />
  </joint>
</robot>
